<?xml version="1.0" ?>
<!-- =================================================================================== -->
<!-- |    This document was autogenerated by xacro from src/custom-ur-descriptions/ur5e_robot_description/urdf/ur_with_zivid_epick.xacro | -->
<!-- |    EDITING THIS FILE BY HAND IS NOT RECOMMENDED                                 | -->
<!-- =================================================================================== -->
<robot name="ur5e">
  <!--   Chain: map -> UR -> flange -> zivid_camera_mount -> zivid_camera -> EPick gripper -->
  <!--
    Base UR robot series xacro macro.

    NOTE this is NOT a URDF. It cannot directly be loaded by consumers
    expecting a flattened '.urdf' file. See the top-level '.xacro' for that
    (but note that .xacro must still be processed by the xacro command).

    This file models the base kinematic chain of a UR robot, which then gets
    parameterised by various configuration files to convert it into a UR3(e),
    UR5(e), UR10(e) or UR16e, etc.

    NOTE the default kinematic parameters (i.e., link lengths, frame locations,
    offsets, etc) do not correspond to any particular robot. They are defaults
    only. There WILL be non-zero offsets between the Forward Kinematics results
    in TF (i.e., robot_state_publisher) and the values reported by the Teach
    Pendant.

    For accurate (and robot-specific) transforms, the 'kinematics_parameters_file'
    parameter MUST point to a .yaml file containing the appropriate values for
    the targeted robot.

    If using the UniversalRobots/Universal_Robots_ROS_Driver, follow the steps
    described in the readme of that repository to extract the kinematic
    calibration from the controller and generate the required .yaml file.

    Main author of the migration to yaml configs Ludovic Delval.

    Contributors to previous versions (in no particular order)

     - Denis Stogl
     - Lovro Ivanov
     - Felix Messmer
     - Kelsey Hawkins
     - Wim Meeussen
     - Shaun Edwards
     - Nadia Hammoudeh Garcia
     - Dave Hershberger
     - G. vd. Hoorn
     - Philip Long
     - Dave Coleman
     - Miguel Prada
     - Mathias Luedtke
     - Marcel Schnirring
     - Felix von Drigalski
     - Felix Exner
     - Jimmy Da Silva
     - Ajit Krisshna N L
     - Muhammad Asif Rana
  -->
  <!--
    NOTE the macro defined in this file is NOT part of the public API of this
          package. Users CANNOT rely on this file being available, or stored in
          this location. Nor can they rely on the existence of the macro.
  -->
  <!--
    Zivid Camera Mount with Direct Hand-Eye Calibration

    Frame chain:
      parent_link (tool0) -> zivid_optical_frame (CALIBRATED - point cloud origin)
      parent_link (tool0) -> zivid_arm_mount -> zivid_base_link (visual mesh only)

    The hand-eye calibration gives us: tool0 -> optical_frame directly.
    We DON'T use the zivid_camera macro's uncalibrated optical joint.
  -->
  <!-- create link fixed to the "map" -->
  <link name="map"/>
  <ros2_control name="ur5e" type="system">
    <hardware>
      <plugin>ur_robot_driver/URPositionHardwareInterface</plugin>
      <param name="robot_ip">0.0.0.0</param>
      <param name="script_filename"></param>
      <param name="output_recipe_filename"></param>
      <param name="input_recipe_filename"></param>
      <param name="headless_mode">False</param>
      <param name="reverse_port">50001</param>
      <param name="script_sender_port">50002</param>
      <param name="reverse_ip">0.0.0.0</param>
      <param name="script_command_port">50004</param>
      <param name="trajectory_port">50003</param>
      <param name="tf_prefix"></param>
      <param name="non_blocking_read">True</param>
      <param name="servoj_gain">2000</param>
      <param name="servoj_lookahead_time">0.03</param>
      <param name="use_tool_communication">False</param>
      <param name="kinematics/hash">calib_12788084448423163542</param>
      <param name="tool_voltage">0</param>
      <param name="tool_parity">0</param>
      <param name="tool_baud_rate">115200</param>
      <param name="tool_stop_bits">1</param>
      <param name="tool_rx_idle_chars">1.5</param>
      <param name="tool_tx_idle_chars">3.5</param>
      <param name="tool_device_name">/tmp/ttyUR</param>
      <param name="tool_tcp_port">54321</param>
      <param name="keep_alive_count">10</param>
    </hardware>
    <joint name="shoulder_pan_joint">
      <command_interface name="position"/>
      <command_interface name="velocity"/>
      <command_interface name="effort"/>
      <state_interface name="position">
        <!-- initial position for the FakeSystem and simulation -->
        <param name="initial_value">1.3914</param>
      </state_interface>
      <state_interface name="velocity"/>
      <state_interface name="effort"/>
    </joint>
    <joint name="shoulder_lift_joint">
      <command_interface name="position"/>
      <command_interface name="velocity"/>
      <command_interface name="effort"/>
      <state_interface name="position">
        <!-- initial position for the FakeSystem and simulation -->
        <param name="initial_value">-1.2132</param>
      </state_interface>
      <state_interface name="velocity"/>
      <state_interface name="effort"/>
    </joint>
    <joint name="elbow_joint">
      <command_interface name="position"/>
      <command_interface name="velocity"/>
      <command_interface name="effort"/>
      <state_interface name="position">
        <!-- initial position for the FakeSystem and simulation -->
        <param name="initial_value">-1.4297</param>
      </state_interface>
      <state_interface name="velocity"/>
      <state_interface name="effort"/>
    </joint>
    <joint name="wrist_1_joint">
      <command_interface name="position"/>
      <command_interface name="velocity"/>
      <command_interface name="effort"/>
      <state_interface name="position">
        <!-- initial position for the FakeSystem and simulation -->
        <param name="initial_value">-2.0584</param>
      </state_interface>
      <state_interface name="velocity"/>
      <state_interface name="effort"/>
    </joint>
    <joint name="wrist_2_joint">
      <command_interface name="position"/>
      <command_interface name="velocity"/>
      <command_interface name="effort"/>
      <state_interface name="position">
        <!-- initial position for the FakeSystem and simulation -->
        <param name="initial_value">-4.6783</param>
      </state_interface>
      <state_interface name="velocity"/>
      <state_interface name="effort"/>
    </joint>
    <joint name="wrist_3_joint">
      <command_interface name="position"/>
      <command_interface name="velocity"/>
      <command_interface name="effort"/>
      <state_interface name="position">
        <!-- initial position for the FakeSystem and simulation -->
        <param name="initial_value">-2.743</param>
      </state_interface>
      <state_interface name="velocity"/>
      <state_interface name="effort"/>
    </joint>
    <sensor name="tcp_fts_sensor">
      <state_interface name="force.x"/>
      <state_interface name="force.y"/>
      <state_interface name="force.z"/>
      <state_interface name="torque.x"/>
      <state_interface name="torque.y"/>
      <state_interface name="torque.z"/>
    </sensor>
    <sensor name="tcp_pose">
      <state_interface name="position.x"/>
      <state_interface name="position.y"/>
      <state_interface name="position.z"/>
      <state_interface name="orientation.x"/>
      <state_interface name="orientation.y"/>
      <state_interface name="orientation.z"/>
      <state_interface name="orientation.w"/>
    </sensor>
    <!-- NOTE The following are joints used only for testing with fake hardware and will change in the future -->
    <gpio name="speed_scaling">
      <state_interface name="speed_scaling_factor"/>
      <param name="initial_speed_scaling_factor">1</param>
      <command_interface name="target_speed_fraction_cmd"/>
      <command_interface name="target_speed_fraction_async_success"/>
    </gpio>
    <gpio name="gpio">
      <command_interface name="standard_digital_output_cmd_0"/>
      <command_interface name="standard_digital_output_cmd_1"/>
      <command_interface name="standard_digital_output_cmd_2"/>
      <command_interface name="standard_digital_output_cmd_3"/>
      <command_interface name="standard_digital_output_cmd_4"/>
      <command_interface name="standard_digital_output_cmd_5"/>
      <command_interface name="standard_digital_output_cmd_6"/>
      <command_interface name="standard_digital_output_cmd_7"/>
      <command_interface name="standard_digital_output_cmd_8"/>
      <command_interface name="standard_digital_output_cmd_9"/>
      <command_interface name="standard_digital_output_cmd_10"/>
      <command_interface name="standard_digital_output_cmd_11"/>
      <command_interface name="standard_digital_output_cmd_12"/>
      <command_interface name="standard_digital_output_cmd_13"/>
      <command_interface name="standard_digital_output_cmd_14"/>
      <command_interface name="standard_digital_output_cmd_15"/>
      <command_interface name="standard_digital_output_cmd_16"/>
      <command_interface name="standard_digital_output_cmd_17"/>
      <command_interface name="standard_analog_output_cmd_0"/>
      <command_interface name="standard_analog_output_cmd_1"/>
      <command_interface name="analog_output_domain_cmd"/>
      <command_interface name="tool_voltage_cmd"/>
      <command_interface name="io_async_success"/>
      <state_interface name="digital_output_0"/>
      <state_interface name="digital_output_1"/>
      <state_interface name="digital_output_2"/>
      <state_interface name="digital_output_3"/>
      <state_interface name="digital_output_4"/>
      <state_interface name="digital_output_5"/>
      <state_interface name="digital_output_6"/>
      <state_interface name="digital_output_7"/>
      <state_interface name="digital_output_8"/>
      <state_interface name="digital_output_9"/>
      <state_interface name="digital_output_10"/>
      <state_interface name="digital_output_11"/>
      <state_interface name="digital_output_12"/>
      <state_interface name="digital_output_13"/>
      <state_interface name="digital_output_14"/>
      <state_interface name="digital_output_15"/>
      <state_interface name="digital_output_16"/>
      <state_interface name="digital_output_17"/>
      <state_interface name="digital_input_0"/>
      <state_interface name="digital_input_1"/>
      <state_interface name="digital_input_2"/>
      <state_interface name="digital_input_3"/>
      <state_interface name="digital_input_4"/>
      <state_interface name="digital_input_5"/>
      <state_interface name="digital_input_6"/>
      <state_interface name="digital_input_7"/>
      <state_interface name="digital_input_8"/>
      <state_interface name="digital_input_9"/>
      <state_interface name="digital_input_10"/>
      <state_interface name="digital_input_11"/>
      <state_interface name="digital_input_12"/>
      <state_interface name="digital_input_13"/>
      <state_interface name="digital_input_14"/>
      <state_interface name="digital_input_15"/>
      <state_interface name="digital_input_16"/>
      <state_interface name="digital_input_17"/>
      <state_interface name="standard_analog_output_0"/>
      <state_interface name="standard_analog_output_1"/>
      <state_interface name="standard_analog_input_0"/>
      <state_interface name="standard_analog_input_1"/>
      <state_interface name="analog_io_type_0"/>
      <state_interface name="analog_io_type_1"/>
      <state_interface name="analog_io_type_2"/>
      <state_interface name="analog_io_type_3"/>
      <state_interface name="tool_mode"/>
      <state_interface name="tool_output_voltage"/>
      <state_interface name="tool_output_current"/>
      <state_interface name="tool_temperature"/>
      <state_interface name="tool_analog_input_0"/>
      <state_interface name="tool_analog_input_1"/>
      <state_interface name="tool_analog_input_type_0"/>
      <state_interface name="tool_analog_input_type_1"/>
      <state_interface name="robot_mode"/>
      <state_interface name="robot_status_bit_0"/>
      <state_interface name="robot_status_bit_1"/>
      <state_interface name="robot_status_bit_2"/>
      <state_interface name="robot_status_bit_3"/>
      <state_interface name="safety_mode"/>
      <state_interface name="safety_status_bit_0"/>
      <state_interface name="safety_status_bit_1"/>
      <state_interface name="safety_status_bit_2"/>
      <state_interface name="safety_status_bit_3"/>
      <state_interface name="safety_status_bit_4"/>
      <state_interface name="safety_status_bit_5"/>
      <state_interface name="safety_status_bit_6"/>
      <state_interface name="safety_status_bit_7"/>
      <state_interface name="safety_status_bit_8"/>
      <state_interface name="safety_status_bit_9"/>
      <state_interface name="safety_status_bit_10"/>
      <state_interface name="program_running"/>
    </gpio>
    <gpio name="payload">
      <command_interface name="mass"/>
      <command_interface name="cog.x"/>
      <command_interface name="cog.y"/>
      <command_interface name="cog.z"/>
      <command_interface name="payload_async_success"/>
    </gpio>
    <gpio name="resend_robot_program">
      <command_interface name="resend_robot_program_cmd"/>
      <command_interface name="resend_robot_program_async_success"/>
    </gpio>
    <gpio name="hand_back_control">
      <command_interface name="hand_back_control_cmd"/>
      <command_interface name="hand_back_control_async_success"/>
    </gpio>
    <gpio name="zero_ftsensor">
      <command_interface name="zero_ftsensor_cmd"/>
      <command_interface name="zero_ftsensor_async_success"/>
    </gpio>
    <gpio name="freedrive_mode">
      <command_interface name="async_success"/>
      <command_interface name="enable"/>
      <command_interface name="abort"/>
    </gpio>
    <gpio name="tool_contact">
      <command_interface name="tool_contact_set_state"/>
      <state_interface name="tool_contact_result"/>
      <state_interface name="tool_contact_state"/>
    </gpio>
    <gpio name="system_interface">
      <state_interface name="initialized"/>
    </gpio>
    <gpio name="force_mode">
      <command_interface name="task_frame_x"/>
      <command_interface name="task_frame_y"/>
      <command_interface name="task_frame_z"/>
      <command_interface name="task_frame_rx"/>
      <command_interface name="task_frame_ry"/>
      <command_interface name="task_frame_rz"/>
      <command_interface name="selection_vector_x"/>
      <command_interface name="selection_vector_y"/>
      <command_interface name="selection_vector_z"/>
      <command_interface name="selection_vector_rx"/>
      <command_interface name="selection_vector_ry"/>
      <command_interface name="selection_vector_rz"/>
      <command_interface name="wrench_x"/>
      <command_interface name="wrench_y"/>
      <command_interface name="wrench_z"/>
      <command_interface name="wrench_rx"/>
      <command_interface name="wrench_ry"/>
      <command_interface name="wrench_rz"/>
      <command_interface name="limits_x"/>
      <command_interface name="limits_y"/>
      <command_interface name="limits_z"/>
      <command_interface name="limits_rx"/>
      <command_interface name="limits_ry"/>
      <command_interface name="limits_rz"/>
      <command_interface name="type"/>
      <command_interface name="damping"/>
      <command_interface name="gain_scaling"/>
      <command_interface name="disable_cmd"/>
      <command_interface name="force_mode_async_success"/>
    </gpio>
    <gpio name="trajectory_passthrough">
      <command_interface name="setpoint_positions_0"/>
      <command_interface name="setpoint_positions_1"/>
      <command_interface name="setpoint_positions_2"/>
      <command_interface name="setpoint_positions_3"/>
      <command_interface name="setpoint_positions_4"/>
      <command_interface name="setpoint_positions_5"/>
      <command_interface name="setpoint_velocities_0"/>
      <command_interface name="setpoint_velocities_1"/>
      <command_interface name="setpoint_velocities_2"/>
      <command_interface name="setpoint_velocities_3"/>
      <command_interface name="setpoint_velocities_4"/>
      <command_interface name="setpoint_velocities_5"/>
      <command_interface name="setpoint_accelerations_0"/>
      <command_interface name="setpoint_accelerations_1"/>
      <command_interface name="setpoint_accelerations_2"/>
      <command_interface name="setpoint_accelerations_3"/>
      <command_interface name="setpoint_accelerations_4"/>
      <command_interface name="setpoint_accelerations_5"/>
      <command_interface name="transfer_state"/>
      <command_interface name="time_from_start"/>
      <command_interface name="abort"/>
    </gpio>
    <gpio name="get_robot_software_version">
      <state_interface name="get_version_major">
        <param name="initial_value">1</param>
      </state_interface>
      <state_interface name="get_version_minor"/>
      <state_interface name="get_version_build"/>
      <state_interface name="get_version_bugfix"/>
    </gpio>
  </ros2_control>
  <!-- Add URDF transmission elements (for ros_control) -->
  <!--<xacro:ur_arm_transmission prefix="${prefix}" hw_interface="${transmission_hw_interface}" />-->
  <!-- Placeholder for ros2_control transmission which don't yet exist -->
  <!-- links -  main serial chain -->
  <link name="base_link"/>
  <link name="base_link_inertia">
    <visual>
      <origin rpy="0 0 3.141592653589793" xyz="0 0 0"/>
      <geometry>
        <mesh filename="package://ur_description/meshes/ur5e/visual/base.dae"/>
      </geometry>
    </visual>
    <collision>
      <origin rpy="0 0 3.141592653589793" xyz="0 0 0"/>
      <geometry>
        <mesh filename="package://ur_description/meshes/ur5e/collision/base.stl"/>
      </geometry>
    </collision>
    <inertial>
      <mass value="4.0"/>
      <origin rpy="0 0 0" xyz="0 0 0"/>
      <inertia ixx="0.00443333156" ixy="0.0" ixz="0.0" iyy="0.00443333156" iyz="0.0" izz="0.0072"/>
    </inertial>
  </link>
  <link name="shoulder_link">
    <visual>
      <origin rpy="0 0 3.141592653589793" xyz="0 0 0"/>
      <geometry>
        <mesh filename="package://ur_description/meshes/ur5e/visual/shoulder.dae"/>
      </geometry>
    </visual>
    <collision>
      <origin rpy="0 0 3.141592653589793" xyz="0 0 0"/>
      <geometry>
        <mesh filename="package://ur_description/meshes/ur5e/collision/shoulder.stl"/>
      </geometry>
    </collision>
    <inertial>
      <mass value="3.761"/>
      <origin rpy="1.570796326794897 0 0" xyz="0.0 -0.00193 -0.02561"/>
      <inertia ixx="0.0070021" ixy="7.3e-07" ixz="-1.053e-05" iyy="0.00648091" iyz="0.00049994" izz="0.00657286"/>
    </inertial>
  </link>
  <link name="upper_arm_link">
    <visual>
      <origin rpy="1.5707963267948966 0 -1.5707963267948966" xyz="0 0 0.138"/>
      <geometry>
        <mesh filename="package://ur_description/meshes/ur5e/visual/upperarm.dae"/>
      </geometry>
    </visual>
    <collision>
      <origin rpy="1.5707963267948966 0 -1.5707963267948966" xyz="0 0 0.138"/>
      <geometry>
        <mesh filename="package://ur_description/meshes/ur5e/collision/upperarm.stl"/>
      </geometry>
    </collision>
    <inertial>
      <mass value="8.058"/>
      <origin rpy="0 0 0" xyz="-0.2125 0.0 0.11336"/>
      <inertia ixx="0.01505885" ixy="-5.4e-05" ixz="5.63e-06" iyy="0.33388086" iyz="-1.81e-06" izz="0.33247207"/>
    </inertial>
  </link>
  <link name="forearm_link">
    <visual>
      <origin rpy="1.5707963267948966 0 -1.5707963267948966" xyz="0 0 0.007"/>
      <geometry>
        <mesh filename="package://ur_description/meshes/ur5e/visual/forearm.dae"/>
      </geometry>
    </visual>
    <collision>
      <origin rpy="1.5707963267948966 0 -1.5707963267948966" xyz="0 0 0.007"/>
      <geometry>
        <mesh filename="package://ur_description/meshes/ur5e/collision/forearm.stl"/>
      </geometry>
    </collision>
    <inertial>
      <mass value="2.846"/>
      <origin rpy="0 0 0" xyz="-0.2422 0.0 0.0265"/>
      <inertia ixx="0.00399632" ixy="-1.365e-05" ixz="0.00137272" iyy="0.07879254" iyz="-6.6e-06" izz="0.0784851"/>
    </inertial>
  </link>
  <link name="wrist_1_link">
    <visual>
      <origin rpy="1.5707963267948966 0 0" xyz="0 0 -0.127"/>
      <geometry>
        <mesh filename="package://ur_description/meshes/ur5e/visual/wrist1.dae"/>
      </geometry>
    </visual>
    <collision>
      <origin rpy="1.5707963267948966 0 0" xyz="0 0 -0.127"/>
      <geometry>
        <mesh filename="package://ur_description/meshes/ur5e/collision/wrist1.stl"/>
      </geometry>
    </collision>
    <inertial>
      <mass value="1.37"/>
      <origin rpy="1.570796326794897 0 0" xyz="0.0 -0.01634 -0.0018"/>
      <inertia ixx="0.00165491" ixy="-2.82e-06" ixz="-4.38e-06" iyy="0.00135962" iyz="0.00010157" izz="0.00126279"/>
    </inertial>
  </link>
  <link name="wrist_2_link">
    <visual>
      <origin rpy="0 0 0" xyz="0 0 -0.0997"/>
      <geometry>
        <mesh filename="package://ur_description/meshes/ur5e/visual/wrist2.dae"/>
      </geometry>
    </visual>
    <collision>
      <origin rpy="0 0 0" xyz="0 0 -0.0997"/>
      <geometry>
        <mesh filename="package://ur_description/meshes/ur5e/collision/wrist2.stl"/>
      </geometry>
    </collision>
    <inertial>
      <mass value="1.3"/>
      <origin rpy="-1.570796326794897 0 0" xyz="0.0 0.01634 -0.0018"/>
      <inertia ixx="0.00135617" ixy="-2.74e-06" ixz="4.44e-06" iyy="0.00127827" iyz="-5.048e-05" izz="0.00096614"/>
    </inertial>
  </link>
  <link name="wrist_3_link">
    <visual>
      <origin rpy="1.5707963267948966 0 0" xyz="0 0 -0.0989"/>
      <geometry>
        <mesh filename="package://ur_description/meshes/ur5e/visual/wrist3.dae"/>
      </geometry>
    </visual>
    <collision>
      <origin rpy="1.5707963267948966 0 0" xyz="0 0 -0.0989"/>
      <geometry>
        <mesh filename="package://ur_description/meshes/ur5e/collision/wrist3.stl"/>
      </geometry>
    </collision>
    <inertial>
      <mass value="0.365"/>
      <origin rpy="0 0 0" xyz="0.0 0.0 -0.001159"/>
      <inertia ixx="0.00018694" ixy="6e-08" ixz="-1.7e-07" iyy="0.00018908" iyz="-9.2e-07" izz="0.00025756"/>
    </inertial>
  </link>
  <!-- base_joint fixes base_link to the environment -->
  <joint name="base_joint" type="fixed">
    <origin rpy="0 0 0" xyz="0 0 0"/>
    <parent link="map"/>
    <child link="base_link"/>
  </joint>
  <!-- joints - main serial chain -->
  <joint name="base_link-base_link_inertia" type="fixed">
    <parent link="base_link"/>
    <child link="base_link_inertia"/>
    <!-- 'base_link' is REP-103 aligned (so X+ forward), while the internal
           frames of the robot/controller have X+ pointing backwards.
           Use the joint between 'base_link' and 'base_link_inertia' (a dummy
           link/frame) to introduce the necessary rotation over Z (of pi rad).
      -->
    <origin rpy="0 0 3.141592653589793" xyz="0 0 0"/>
  </joint>
  <joint name="shoulder_pan_joint" type="revolute">
    <parent link="base_link_inertia"/>
    <child link="shoulder_link"/>
    <origin rpy="0 0 0" xyz="0 0 0.1625"/>
    <axis xyz="0 0 1"/>
    <limit effort="150.0" lower="-6.283185307179586" upper="6.283185307179586" velocity="3.141592653589793"/>
    <dynamics damping="0" friction="0"/>
  </joint>
  <joint name="shoulder_lift_joint" type="revolute">
    <parent link="shoulder_link"/>
    <child link="upper_arm_link"/>
    <origin rpy="1.570796327 0 0" xyz="0 0 0"/>
    <axis xyz="0 0 1"/>
    <limit effort="150.0" lower="-6.283185307179586" upper="6.283185307179586" velocity="3.141592653589793"/>
    <dynamics damping="0" friction="0"/>
  </joint>
  <joint name="elbow_joint" type="revolute">
    <parent link="upper_arm_link"/>
    <child link="forearm_link"/>
    <origin rpy="0 0 0" xyz="-0.425 0 0"/>
    <axis xyz="0 0 1"/>
    <limit effort="150.0" lower="-3.141592653589793" upper="3.141592653589793" velocity="3.141592653589793"/>
    <dynamics damping="0" friction="0"/>
  </joint>
  <joint name="wrist_1_joint" type="revolute">
    <parent link="forearm_link"/>
    <child link="wrist_1_link"/>
    <origin rpy="0 0 0" xyz="-0.3922 0 0.1333"/>
    <axis xyz="0 0 1"/>
    <limit effort="28.0" lower="-6.283185307179586" upper="6.283185307179586" velocity="3.141592653589793"/>
    <dynamics damping="0" friction="0"/>
  </joint>
  <joint name="wrist_2_joint" type="revolute">
    <parent link="wrist_1_link"/>
    <child link="wrist_2_link"/>
    <origin rpy="1.570796327 0 0" xyz="0 -0.0997 -2.044881182297852e-11"/>
    <axis xyz="0 0 1"/>
    <limit effort="28.0" lower="-6.283185307179586" upper="6.283185307179586" velocity="3.141592653589793"/>
    <dynamics damping="0" friction="0"/>
  </joint>
  <joint name="wrist_3_joint" type="revolute">
    <parent link="wrist_2_link"/>
    <child link="wrist_3_link"/>
    <origin rpy="1.570796326589793 3.141592653589793 3.141592653589793" xyz="0 0.0996 -2.042830148012698e-11"/>
    <axis xyz="0 0 1"/>
    <limit effort="28.0" lower="-6.283185307179586" upper="6.283185307179586" velocity="3.141592653589793"/>
    <dynamics damping="0" friction="0"/>
  </joint>
  <link name="ft_frame"/>
  <joint name="wrist_3_link-ft_frame" type="fixed">
    <parent link="wrist_3_link"/>
    <child link="ft_frame"/>
    <origin rpy="3.141592653589793 0 0" xyz="0 0 0"/>
  </joint>
  <!-- ROS-Industrial 'base' frame - base_link to UR 'Base' Coordinates transform -->
  <link name="base"/>
  <joint name="base_link-base_fixed_joint" type="fixed">
    <!-- Note the rotation over Z of pi radians - as base_link is REP-103
           aligned (i.e., has X+ forward, Y+ left and Z+ up), this is needed
           to correctly align 'base' with the 'Base' coordinate system of
           the UR controller.
      -->
    <origin rpy="0 0 3.141592653589793" xyz="0 0 0"/>
    <parent link="base_link"/>
    <child link="base"/>
  </joint>
  <!-- ROS-Industrial 'flange' frame - attachment point for EEF models -->
  <link name="flange"/>
  <joint name="wrist_3-flange" type="fixed">
    <parent link="wrist_3_link"/>
    <child link="flange"/>
    <origin rpy="0 -1.5707963267948966 -1.5707963267948966" xyz="0 0 0"/>
  </joint>
  <!-- ROS-Industrial 'tool0' frame - all-zeros tool frame -->
  <link name="tool0"/>
  <joint name="flange-tool0" type="fixed">
    <!-- default toolframe - X+ left, Y+ up, Z+ front -->
    <origin rpy="1.5707963267948966 0 1.5707963267948966" xyz="0 0 0"/>
    <parent link="flange"/>
    <child link="tool0"/>
  </joint>
  <!-- ============================================================ -->
  <!-- CALIBRATED OPTICAL FRAME (for point cloud data)              -->
  <!-- This is where the Zivid point cloud is referenced            -->
  <!-- Hand-eye calibration result: tool0 -> zivid_optical_frame    -->
  <!-- ============================================================ -->
  <link name="zivid_optical_frame"/>
  <joint name="tool0_to_zivid_optical" type="fixed">
    <parent link="tool0"/>
    <child link="zivid_optical_frame"/>
    <!-- Hand-eye calibration: tool0 -> optical_frame -->
    <!-- Rotation: Euler XYZ extrinsic, radians | Translation: meters -->
    <!-- Calibration (2026-01-15): Residuals: rot < 0.22°, trans < 0.47mm -->
    <origin rpy="-0.00615 0.04362 3.13541" xyz="0.05675 0.10322 0.05489"/>
    <!-- TEST (2026-01-22): Zero roll/pitch - did NOT help Y variance
      <origin xyz="0.05675 0.10322 0.05489"
              rpy="0 0 3.14159"/> -->
    <!-- Calibration (2025-12-17):
      <origin xyz="0.05659 0.10548 0.05660"
              rpy="-0.01432 0.04829 3.13430"/> -->
    <!-- Calibration (2026-01-13) - had offset issues:
      <origin xyz="0.05646 0.10182 0.05680"
              rpy="-0.03542 0.04745 3.13222"/> -->
    <!-- Old calibration (2025-10-09):
      <origin xyz="0.02803 0.07664 0.0"
              rpy="0.53964 -1.53712 -2.13794"/> -->
  </joint>
  <!-- ============================================================ -->
  <!-- ARM MOUNT (for attaching grippers via tool_block)            -->
  <!-- ============================================================ -->
  <link name="zivid_arm_mount">
    <visual>
      <origin rpy="0 0 0" xyz="0 0 0"/>
      <geometry>
        <!-- Official Zivid On-Arm Mount (from zivid.com/downloads) -->
        <mesh filename="package://ur5e_robot_description/meshes/zivid/zivid_onarm_mount.stl" scale="0.001 0.001 0.001"/>
      </geometry>
      <material name="mount_dark">
        <color rgba="0.2 0.2 0.2 1.0"/>
      </material>
    </visual>
    <collision>
      <origin rpy="0 0 0" xyz="0 0 0"/>
      <geometry>
        <mesh filename="package://ur5e_robot_description/meshes/zivid/zivid_onarm_mount.stl" scale="0.001 0.001 0.001"/>
      </geometry>
    </collision>
    <inertial>
      <mass value="0.170"/>
      <origin rpy="0 0 0" xyz="0 0 0"/>
      <inertia ixx="0.0003" ixy="0.0" ixz="0.0" iyy="0.0005" iyz="0.0" izz="0.0006"/>
    </inertial>
  </link>
  <joint name="zivid_arm_mount_joint" type="fixed">
    <parent link="tool0"/>
    <child link="zivid_arm_mount"/>
    <origin rpy="0 0 0" xyz="0 0 0.005"/>
  </joint>
  <!-- ============================================================ -->
  <!-- CAMERA VISUAL MESH (for RViz visualization)                  -->
  <!-- Positioned relative to optical frame using inverse offset    -->
  <!-- ============================================================ -->
  <link name="zivid_base_link">
    <visual>
      <origin rpy="0 0 1.5707963267948966" xyz="0 0 0"/>
      <geometry>
        <mesh filename="package://zivid_description/meshes/visual/zivid_2_plus.stl"/>
      </geometry>
      <material name="zivid_gray">
        <color rgba="0.3 0.3 0.3 1.0"/>
      </material>
    </visual>
    <collision>
      <origin rpy="0 0 1.5707963267948966" xyz="0 0 0"/>
      <geometry>
        <mesh filename="package://zivid_description/meshes/collision/zivid_2_plus_convex_hull.stl"/>
      </geometry>
    </collision>
  </link>
  <!-- Position visual mesh relative to optical frame -->
  <!-- INVERSE of Zivid's factory transform (base_link → optical_frame) -->
  <!-- Source: zivid_description/urdf/macros/zivid_camera.xacro (ZIVID_2_PLUS_MR60) -->
  <!-- Forward: xyz=(0.049, 0.03202, 0.0295), rpy=(-90°, 0°, -92.5°) -->
  <!-- Inverse: T_inv = [R^T | -R^T * t] computed mathematically -->
  <joint name="optical_to_base_link" type="fixed">
    <parent link="zivid_optical_frame"/>
    <child link="zivid_base_link"/>
    <origin rpy="-1.57080 -1.52716 3.14159" xyz="0.03413 0.02950 -0.04756"/>
  </joint>
  <link name="tool_block">
    <visual>
      <origin rpy="0 0 0" xyz="0 0 0"/>
      <geometry>
        <mesh filename="package://ur5e_robot_description/meshes/tool_exchanger/Tool_block.stl" scale="0.001 0.001 0.001"/>
      </geometry>
      <material name="grey">
        <color rgba="0.5 0.5 0.5 1.0"/>
      </material>
    </visual>
    <collision>
      <origin rpy="0 0 0" xyz="0 0 0"/>
      <geometry>
        <mesh filename="package://ur5e_robot_description/meshes/tool_exchanger/Tool_block.stl" scale="0.001 0.001 0.001"/>
      </geometry>
    </collision>
    <inertial>
      <mass value="0.2"/>
      <origin rpy="0 0 0" xyz="0 0 0"/>
      <inertia ixx="0.001" ixy="0.0" ixz="0.0" iyy="0.001" iyz="0.0" izz="0.001"/>
    </inertial>
  </link>
  <joint name="tool_block_joint" type="fixed">
    <parent link="zivid_arm_mount"/>
    <child link="tool_block"/>
    <origin rpy="-1.5708 0 3.14159" xyz="0 0 0.051"/>
  </joint>
  <ros2_control name="epick_driver_ros2_control" type="system">
    <hardware>
      <plugin>epick_driver/EpickGripperHardwareInterface</plugin>
      <!-- Serial connection parameters ////////////////////////////////// -->
      <param name="usb_port">/tmp/ttyUR</param>
      <param name="baud_rate">115200</param>
      <param name="timeout">0.2</param>
      <!-- Gripper parameters /////////////////////////////////////////// -->
      <!-- Set use_dummy to true to connect to a dummy driver for testing purposes. -->
      <param name="use_dummy">False</param>
      <!-- The address of the gripper. -->
      <param name="slave_address">0x9</param>
      <!-- The gripper operation mode: AutomaticMode or AdvancedMode. -->
      <param name="mode">AdvancedMode</param>
      <!-- The following parameters are only required for the AdvancedMode. -->
      <param name="grip_max_vacuum_pressure">-60</param>
      <param name="grip_min_vacuum_pressure">-10</param>
      <param name="grip_timeout">25.0</param>
      <param name="release_timeout">2.0</param>
    </hardware>
    <gpio name="gripper">
      <!--
          Command interface to control the gripper:
          1.0 = grip
          0.0 = release
        -->
      <command_interface name="grip_cmd"/>
      <!--
          State interface that follows the value of the gripper/grip_cmd
          command interface:
          1.0 = successful grip
          0.0 = successful release
        -->
      <state_interface name="grip_cmd"/>
      <!--
          Return the object detection status:
          0.0 = unknown
          1.0 = object detected at minimum pressure
          2.0 = object detected at maximum pressure
          3.0 = no object detected
        -->
      <state_interface name="object_detection_status"/>
    </gpio>
    <!--
        This is optional configuration if you want to publish the state of the
        gripper as a joint state interface.
      -->
    <joint name="gripper">
      <!--
          State interface that follows the value of the gripper/grip_cmd
          command interface:
          1.0 = successful grip
          0.0 = successful release
        -->
      <state_interface name="position"/>
    </joint>
  </ros2_control>
  <!-- Base Link -->
  <link name="epick_base_link"/>
  <joint name="tool_block_to_epick_base_link" type="fixed">
    <parent link="tool_block"/>
    <child link="epick_base_link"/>
    <origin rpy="-1.5708 0 3.1416" xyz="0 -0.03235 0"/>
  </joint>
  <!-- EPick Body -->
  <link name="epick_body">
    <visual>
      <!-- Shifted backwards since the mesh origin is at the base end -->
      <origin rpy="0 0 0" xyz="0 0 -0.05115"/>
      <geometry>
        <mesh filename="package://epick_description/meshes/visual/epick_body.stl" scale="0.001 0.001 0.001"/>
      </geometry>
      <material name="epick_gray">
        <color rgba="0.25 0.25 0.25 1"/>
      </material>
    </visual>
    <collision>
      <origin rpy="0 0 0" xyz="0 0 0"/>
      <geometry>
        <cylinder length="0.1023" radius="0.044"/>
      </geometry>
    </collision>
  </link>
  <joint name="epick_base_link_to_epick_body" type="fixed">
    <parent link="epick_base_link"/>
    <child link="epick_body"/>
    <origin rpy="0 0 0" xyz="0 0 0.05115"/>
  </joint>
  <link name="epick_extension">
    <visual>
      <origin rpy="0 0 0" xyz="0 0 0"/>
      <geometry>
        <cylinder length="0.037" radius="0.001"/>
      </geometry>
      <material name="">
        <color rgba="0.25 0.25 0.25 1"/>
      </material>
    </visual>
    <collision>
      <origin rpy="0 0 0" xyz="0 0 0"/>
      <geometry>
        <cylinder length="0.037" radius="0.001"/>
      </geometry>
    </collision>
  </link>
  <joint name="epick_body_to_epick_extension" type="fixed">
    <parent link="epick_body"/>
    <child link="epick_extension"/>
    <origin rpy="0 0 0" xyz="0 0 0.06965"/>
  </joint>
  <link name="epick_suction_cup">
    <visual>
      <origin rpy="0 0 0" xyz="0 0 0"/>
      <geometry>
        <cylinder length="0.002" radius="0.0035"/>
      </geometry>
      <material name="">
        <color rgba="0.25 0.25 0.25 1"/>
      </material>
    </visual>
    <collision>
      <origin rpy="0 0 0" xyz="0 0 0"/>
      <geometry>
        <cylinder length="0.002" radius="0.0035"/>
      </geometry>
    </collision>
  </link>
  <joint name="epick_extension_to_epick_suction_cup" type="fixed">
    <parent link="epick_extension"/>
    <child link="epick_suction_cup"/>
    <origin rpy="0 0 0" xyz="0 0 0.0195"/>
  </joint>
  <!-- TIP Frame -->
  <!-- represents the outmost point of the collision geometry -->
  <link name="epick_tip"/>
  <joint name="epick_suction_cup_to_epick_tip" type="fixed">
    <parent link="epick_suction_cup"/>
    <child link="epick_tip"/>
    <origin rpy="0 0 0" xyz="0 0 0.001"/>
  </joint>
  <!-- TCP Frame -->
  <!-- contact point to use for IK, Z-axis points "forwards", recessed by tcp_stroke_compensation -->
  <link name="epick_tcp"/>
  <joint name="epick_tip_to_epick_tcp" type="fixed">
    <parent link="epick_tip"/>
    <child link="epick_tcp"/>
    <origin rpy="0 0 0" xyz="0 0 -0.0"/>
  </joint>
  <!-- To allow MoveIt to actuate the gripper as part of a trajectory, we need to include a fake "joint" in the URDF corresponding to the Epick's vacuum state. -->
  <link name="epick_vacuum_state"/>
  <joint name="gripper" type="revolute">
    <origin rpy="0 0 0" xyz="0 0 0"/>
    <parent link="epick_tcp"/>
    <child link="epick_vacuum_state"/>
    <limit effort="30" lower="0.0" upper="1.0" velocity="1.0"/>
  </joint>
</robot>
